Traceback (most recent call last):
  File "/home/jnear/anaconda3/envs/book/lib/python3.6/site-packages/jupyter_cache/executors/utils.py", line 56, in single_nb_execution
    record_timing=False,
  File "/home/jnear/anaconda3/envs/book/lib/python3.6/site-packages/nbclient/client.py", line 1077, in execute
    return NotebookClient(nb=nb, resources=resources, km=km, **kwargs).execute()
  File "/home/jnear/anaconda3/envs/book/lib/python3.6/site-packages/nbclient/util.py", line 74, in wrapped
    return just_run(coro(*args, **kwargs))
  File "/home/jnear/anaconda3/envs/book/lib/python3.6/site-packages/nbclient/util.py", line 53, in just_run
    return loop.run_until_complete(coro)
  File "/home/jnear/anaconda3/envs/book/lib/python3.6/asyncio/base_events.py", line 488, in run_until_complete
    return future.result()
  File "/home/jnear/anaconda3/envs/book/lib/python3.6/site-packages/nbclient/client.py", line 527, in async_execute
    cell, index, execution_count=self.code_cells_executed + 1
  File "/home/jnear/anaconda3/envs/book/lib/python3.6/site-packages/nbclient/client.py", line 822, in async_execute_cell
    self._check_raise_for_error(cell, exec_reply)
  File "/home/jnear/anaconda3/envs/book/lib/python3.6/site-packages/nbclient/client.py", line 730, in _check_raise_for_error
    raise CellExecutionError.from_cell_and_msg(cell, exec_reply['content'])
nbclient.exceptions.CellExecutionError: An error occurred while executing the following cell:
------------------
f = matplotlib.font_manager.FontProperties(family='Roboto Condensed', weight='bold')
f
------------------

[0;31m---------------------------------------------------------------------------[0m
[0;31mNameError[0m                                 Traceback (most recent call last)
[0;32m<ipython-input-3-7140fc272a17>[0m in [0;36m<module>[0;34m[0m
[0;32m----> 1[0;31m [0mf[0m [0;34m=[0m [0mmatplotlib[0m[0;34m.[0m[0mfont_manager[0m[0;34m.[0m[0mFontProperties[0m[0;34m([0m[0mfamily[0m[0;34m=[0m[0;34m'Roboto Condensed'[0m[0;34m,[0m [0mweight[0m[0;34m=[0m[0;34m'bold'[0m[0;34m)[0m[0;34m[0m[0;34m[0m[0m
[0m[1;32m      2[0m [0mf[0m[0;34m[0m[0;34m[0m[0m

[0;31mNameError[0m: name 'matplotlib' is not defined
NameError: name 'matplotlib' is not defined

